ERROR 2020-02-15 23:05:09,844 Module:app --- Exception occurred
Traceback (most recent call last):
  File "service/app.py", line 39, in get_recommended_styles
    validity = relevance_model.get_validity(text)
  File "/Users/300018290/PycharmProjects/relevanceApp/service/model/relevance_model.py", line 13, in get_validity
    embeddings = self.parse_data(text)
  File "/Users/300018290/PycharmProjects/relevanceApp/service/model/relevance_model.py", line 10, in parse_data
    return parse_text([text], self.processor)
  File "/Users/300018290/PycharmProjects/relevanceApp/pipeline/preprocessing.py", line 3, in parse_text
    return count_vectorizer.transform(data)
  File "/Users/300018290/PycharmProjects/relevanceApp/venv/lib/python3.7/site-packages/sklearn/feature_extraction/text.py", line 1267, in transform
    self._check_vocabulary()
  File "/Users/300018290/PycharmProjects/relevanceApp/venv/lib/python3.7/site-packages/sklearn/feature_extraction/text.py", line 490, in _check_vocabulary
    raise NotFittedError("Vocabulary not fitted or provided")
sklearn.exceptions.NotFittedError: Vocabulary not fitted or provided
ERROR 2020-02-16 00:25:24,147 Module:app --- Exception occurred
Traceback (most recent call last):
  File "service/app.py", line 41, in get_recommended_styles
    validity = relevance_model.get_validity(text)
  File "/Users/300018290/PycharmProjects/relevanceApp/service/model/relevance_model.py", line 13, in get_validity
    embeddings = self.parse_data(text)
  File "/Users/300018290/PycharmProjects/relevanceApp/service/model/relevance_model.py", line 10, in parse_data
    return parse_text([text], self.processor)
  File "/Users/300018290/PycharmProjects/relevanceApp/pipeline/preprocessing.py", line 4, in parse_text
    return count_vectorizer.transform(data)
  File "/Users/300018290/PycharmProjects/relevanceApp/venv/lib/python3.7/site-packages/sklearn/feature_extraction/text.py", line 1267, in transform
    self._check_vocabulary()
  File "/Users/300018290/PycharmProjects/relevanceApp/venv/lib/python3.7/site-packages/sklearn/feature_extraction/text.py", line 490, in _check_vocabulary
    raise NotFittedError("Vocabulary not fitted or provided")
sklearn.exceptions.NotFittedError: Vocabulary not fitted or provided
ERROR 2020-02-16 00:27:31,258 Module:app --- Exception occurred
Traceback (most recent call last):
  File "service/app.py", line 41, in get_recommended_styles
    validity = relevance_model.get_validity(text)
  File "/Users/300018290/PycharmProjects/relevanceApp/service/model/relevance_model.py", line 13, in get_validity
    embeddings = self.parse_data(text)
  File "/Users/300018290/PycharmProjects/relevanceApp/service/model/relevance_model.py", line 10, in parse_data
    return parse_text([text], self.processor)
  File "/Users/300018290/PycharmProjects/relevanceApp/pipeline/preprocessing.py", line 2, in parse_text
    def parse_text(data, count_vectorizer):
  File "/usr/local/Cellar/python@3.7/3.7.6/Frameworks/Python.framework/Versions/3.7/lib/python3.7/bdb.py", line 90, in trace_dispatch
    return self.dispatch_call(frame, arg)
  File "/usr/local/Cellar/python@3.7/3.7.6/Frameworks/Python.framework/Versions/3.7/lib/python3.7/bdb.py", line 135, in dispatch_call
    if self.quitting: raise BdbQuit
bdb.BdbQuit
ERROR 2020-02-16 00:28:29,795 Module:app --- Exception occurred
Traceback (most recent call last):
  File "service/app.py", line 38, in get_recommended_styles
    json_data = json.loads(request.data)
  File "/Users/300018290/PycharmProjects/relevanceApp/service/model/relevance_model.py", line 13, in get_validity
    embeddings = self.parse_data(text)
  File "/Users/300018290/PycharmProjects/relevanceApp/service/model/relevance_model.py", line 10, in parse_data
    return parse_text([text], self.processor)
  File "/Users/300018290/PycharmProjects/relevanceApp/pipeline/preprocessing.py", line 4, in parse_text
    return count_vectorizer.transform(data)
  File "/Users/300018290/PycharmProjects/relevanceApp/pipeline/preprocessing.py", line 4, in parse_text
    return count_vectorizer.transform(data)
  File "/usr/local/Cellar/python@3.7/3.7.6/Frameworks/Python.framework/Versions/3.7/lib/python3.7/bdb.py", line 88, in trace_dispatch
    return self.dispatch_line(frame)
  File "/usr/local/Cellar/python@3.7/3.7.6/Frameworks/Python.framework/Versions/3.7/lib/python3.7/bdb.py", line 113, in dispatch_line
    if self.quitting: raise BdbQuit
bdb.BdbQuit
ERROR 2020-02-16 00:29:38,779 Module:app --- Exception occurred
Traceback (most recent call last):
  File "service/app.py", line 41, in get_recommended_styles
    validity = relevance_model.get_validity(text)
  File "/Users/300018290/PycharmProjects/relevanceApp/service/model/relevance_model.py", line 15, in get_validity
    "is_valid": self.processor.predict(embeddings)
AttributeError: 'CountVectorizer' object has no attribute 'predict'
ERROR 2020-02-16 00:30:02,017 Module:app --- Exception occurred
Traceback (most recent call last):
  File "service/app.py", line 41, in get_recommended_styles
    validity = relevance_model.get_validity(text)
  File "/Users/300018290/PycharmProjects/relevanceApp/service/model/relevance_model.py", line 15, in get_validity
    "is_valid": self.classifier.predict(embeddings)
AttributeError: 'CountVectorizer' object has no attribute 'predict'
ERROR 2020-02-16 00:31:32,995 Module:app --- Exception occurred
Traceback (most recent call last):
  File "service/app.py", line 38, in get_recommended_styles
    json_data = json.loads(request.data)
  File "/Users/300018290/PycharmProjects/relevanceApp/service/model/relevance_model.py", line 15, in get_validity
    "is_valid": self.classifier.predict(embeddings)
AttributeError: 'CountVectorizer' object has no attribute 'predict'
ERROR 2020-02-16 01:06:13,680 Module:app --- Exception occurred
Traceback (most recent call last):
  File "service/app.py", line 38, in get_recommended_styles
    json_data = json.loads(request.data)
  File "/Users/300018290/PycharmProjects/relevanceApp/service/model/relevance_model.py", line 15, in get_validity
    return {
AttributeError: 'CountVectorizer' object has no attribute 'predict'
ERROR 2020-02-16 01:07:47,763 Module:app --- Exception occurred
Traceback (most recent call last):
  File "service/app.py", line 38, in get_recommended_styles
    # flask_logger.info("recommend for uidx: " + str() )
  File "/Users/300018290/PycharmProjects/relevanceApp/service/model/relevance_model.py", line 16, in get_validity
    }
  File "/Users/300018290/PycharmProjects/relevanceApp/service/model/relevance_model.py", line 16, in get_validity
    }
  File "/usr/local/Cellar/python@3.7/3.7.6/Frameworks/Python.framework/Versions/3.7/lib/python3.7/bdb.py", line 88, in trace_dispatch
    return self.dispatch_line(frame)
  File "/usr/local/Cellar/python@3.7/3.7.6/Frameworks/Python.framework/Versions/3.7/lib/python3.7/bdb.py", line 113, in dispatch_line
    if self.quitting: raise BdbQuit
bdb.BdbQuit
